<!DOCTYPE html>
<html lang="en">
    <head>
        <link
          rel="stylesheet"
          href="https://fonts.googleapis.com/css?family=Open+Sans:300,300italic,400,400italic,600,600italic%7CNoto+Serif:400,400italic,700,700italic%7CDroid+Sans+Mono:400,700"
        />
        <script src="../js/13/run_pprettify.js"></script>
        <link rel="stylesheet" href="../css/style.css" />
        <link rel="stylesheet" href="../css/pretty.css" />
      </head>
<body>



<div id="header">
    <h2 id="_1">async/await 是什麼？</h2>
    <div class="sectionbody">
        <div class="ulist">
            <h3>1. async 語法</h3>
            <p>
                使用 async 關鍵字聲明的函式為非同步函式，非同步函式會返回一個 Promise 物件，而非直接返回函式執行的結果。讓我們透過範例來了解:
            </p>
            <h4>普通函式：</h4>
            <pre class="prettyprint">
function f1() {
    return "Hello! ExplainThis!";
}

f1(); // 輸出: "Hello! ExplainThis!"
            </pre>
            <p>使用 async 時，會自動將回傳值包裝在一個 Promise 物件當中：</p>
            <pre class="prettyprint">
async function f2() {
    return "Hello! ExplainThis!";
}

f2(); // 輸出: Promise {<fulfilled>: 'Hello! ExplainThis!'}
            </pre>

            <h3>2. await 語法</h3>
            <p>
                await 是一個運算子，用於等待一個 Promise 完成或拒絕。它通常與 async 函式一起使用，因為只有在 async 函式內部或模組的頂層，才能使用 await。當使用 await 時，程式會暫停執行該 async 函式，直到 await 等待的 Promise 完成並回傳結果後，才會繼續往下執行。
            </p>
            <pre class="prettyprint">
async function getData() {
    // await 等待 fetch 這個非同步函式返回一個 Promise 並解析它
    const res = await fetch("https://example.com/data");

    // await 等待上一步的 Promise 解析後，再解析它的 JSON 資料
    const data = await res.json();

    // 前面兩步都完成後，才會執行這一行並印出資料
    console.log(data);
}

getData();
            </pre>

            <h4>使用 await 要注意的地方：</h4>
            <p>在非 async 函式中使用 await 會報 SyntaxError 的錯誤</p>
            <pre class="prettyprint">
function f() {
    let promise = Promise.resolve("Hello! ExplainThis!");
    let result = await promise;
}

// Uncaught SyntaxError: await is only valid in async functions and the top level bodies of modules
            </pre>

            <h3>3. 用 Promise 來寫一個 getData 函式的例子：</h3>
            <pre class="prettyprint">
function getData() {
    fetch(url)
        .then(response => {
    if (!response.ok) {
        throw new Error('Network response was not ok');
        }
            return response.json(); // 將回應轉換為JSON
        })
    .then(data => console.log(data)) // 處理取得的資料
    .catch(error => console.error('There was a problem with the fetch operation:', error)); // 捕獲並處理錯誤
        }
                
    getData();
                
            </pre>

            <h3>4. 使用 async/await 重寫：</h3>
            <pre class="prettyprint">
async function getData(url) {
    try {
        const res = await fetch(url);
        const data = await res.json();
        console.log(data);
    } catch (error) {
        console.error(error);
    }
}

getData("https://example.com/data");
            </pre>

            <h3>總結</h3>
            <ul>
                <li><strong>可讀性：</strong>async/await 提供了更簡潔、更直觀的語法，使得非同步程式碼更易讀和維護。Promise 
                    則需要使用 then 和 catch 方法來處理結果和錯誤，語法上較為冗長。</li>
                <li><strong>錯誤處理：</strong>在 async/await 中，可以直接使用 try...catch 來捕獲錯誤，而在 Promise 中需要使用 catch 方法。</li>
            </ul>
        </div>
    </div>
</div>



<div id="header">
    <h2 id="_1">try/catch 錯誤處理</h2>
    <div class="sectionbody">
        <div class="ulist">
            <p>
                Promise：使用 .catch() 來處理錯誤，但如果有多層 .then()，錯誤處理的邏輯會比較分散。每個 Promise 都需要明確捕捉錯誤，否則容易遺漏。
            </p>

            <h3>1. 使用 Promise + .then() 和 .catch() 處理錯誤</h3>
            <p>
                在此範例中，使用 .catch() 來處理錯誤，但如果有多層 .then()，錯誤處理的邏輯會比較分散。每個 Promise 都需要明確捕捉錯誤，否則容易遺漏。
            </p>
            <pre class="prettyprint">
function fetchDataWithPromise() {
    fetch('https://api.example.com/data1')
        .then(response => {
            if (!response.ok) {
                throw new Error('Failed to fetch data1');
            }
            return response.json();
        })
        .then(data1 => {
            console.log('Data1:', data1);
            return fetch('https://api.example.com/data2');
        })
        .then(response => {
            if (!response.ok) {
                throw new Error('Failed to fetch data2');
            }
            return response.json();
        })
        .then(data2 => {
            console.log('Data2:', data2);
            return fetch('https://api.example.com/data3');
        })
        .then(response => {
            if (!response.ok) {
                throw new Error('Failed to fetch data3');
            }
            return response.json();
        })
        .then(data3 => {
            console.log('Data3:', data3);
        })
        .catch(error => {
            console.error('Error occurred:', error.message);
        });
}

fetchDataWithPromise();
            </pre>

            <p>我們串接了多個 .then() 來處理不同的 API 請求，每個請求都有各自的錯誤處理邏輯。如果其中任何一個請求失敗，錯誤會傳遞到最後的 .catch()，但這種方式下，錯誤處理的邏輯較為分散，所以重複撰寫 if (!response.ok) 來檢查每個回應。</p>

            <h3>2. 使用 async/await 與 try/catch 集中錯誤處理</h3>
            <p>
                這個方法將非同步操作包裹在一個 try/catch 區塊中，所有的錯誤處理都集中在一起，更適合處理多層次的非同步操作，程式碼結構更簡潔一致。
            </p>
            <pre class="prettyprint">
async function fetchDataWithAsyncAwait() {
    try {
        const response1 = await fetch('https://api.example.com/data1');
        if (!response1.ok) {
            throw new Error('Failed to fetch data1');
        }
        const data1 = await response1.json();
        console.log('Data1:', data1);

        const response2 = await fetch('https://api.example.com/data2');
        if (!response2.ok) {
            throw new Error('Failed to fetch data2');
        }
        const data2 = await response2.json();
        console.log('Data2:', data2);

        const response3 = await fetch('https://api.example.com/data3');
        if (!response3.ok) {
            throw new Error('Failed to fetch data3');
        }
        const data3 = await response3.json();
        console.log('Data3:', data3);
    } catch (error) {
        console.error('Error occurred:', error.message);
    }
}

fetchDataWithAsyncAwait();
            </pre>

            <p>如果任何一個請求失敗，錯誤會直接跳轉到 catch，不需要在每個 await 後面特別進行錯誤捕捉。這種結構使得錯誤處理邏輯集中在一個區塊內，程式碼更容易維護且可讀性更高。</p>

            <h3>結論</h3>
            <ul>
                <li><strong>Promise + .then()/.catch()：</strong>Promise 的錯誤處理會隨著 .then() 層級的增多而變得分散。</li>
                <li><strong>async/await + try/catch：</strong>可以將所有的非同步操作包裹在一個 try/catch 區塊中，錯誤處理更集中，結構更簡單清晰。</li>
                <br><br>
                
            </ul>

        </div>
    </div>

  

</body>
</html>
